<?xml version="1.0"?>
<robot name="my_robot">

  <!-- Materials -->
  <material name="gray">
    <color rgba="0.5 0.5 0.5 1"/>
  </material>
  <material name="red">
    <color rgba="0.8 0.1 0.1 1"/>
  </material>
  <material name="white">
    <color rgba="0.9 0.9 0.9 1"/>
  </material>
  <material name="black">
    <color rgba="0.1 0.1 0.1 1"/>
  </material>

  <!-- World link -->
  <link name="world"/>

  <!-- World to Base Joint -->
  <joint name="world_to_base" type="fixed">
    <parent link="world"/>
    <child link="base_link"/>
    <origin xyz="0 0 0" rpy="0 0 0"/>
  </joint>

  <!-- Base Link -->
  <link name="base_link">
    <visual>
      <origin xyz="0 0 0.05" rpy="0 0 0"/>
      <geometry>
        <box size="0.2 0.2 0.1"/>
      </geometry>
      <material name="gray"/>
    </visual>
    <collision>
      <origin xyz="0 0 0.05" rpy="0 0 0"/>
      <geometry>
        <box size="0.2 0.2 0.1"/>
      </geometry>
    </collision>
    <inertial>
      <origin xyz="0 0 0.05" rpy="0 0 0"/>
      <mass value="2.0"/>
      <inertia ixx="0.0083" ixy="0.0" ixz="0.0" iyy="0.0083" iyz="0.0" izz="0.0133"/>
    </inertial>
  </link>

  <!-- Joint 1: Base to Link 1 (Revolute Z) -->
  <joint name="joint_1" type="revolute">
    <parent link="base_link"/>
    <child link="link_1"/>
    <origin xyz="0 0 0.1" rpy="0 0 0"/>
    <axis xyz="0 0 1"/>
    <limit lower="-3.14" upper="3.14" effort="10.0" velocity="1.0"/>
  </joint>

  <!-- Link 1 -->
  <link name="link_1">
    <visual>
      <origin xyz="0 0 0.15" rpy="0 0 0"/>
      <geometry>
        <cylinder length="0.3" radius="0.05"/>
      </geometry>
      <material name="red"/>
    </visual>
    <collision>
      <origin xyz="0 0 0.15" rpy="0 0 0"/>
      <geometry>
        <cylinder length="0.3" radius="0.05"/>
      </geometry>
    </collision>
    <inertial>
      <origin xyz="0 0 0.15" rpy="0 0 0"/>
      <mass value="0.6"/>
      <inertia ixx="0.004875" ixy="0.0" ixz="0.0" iyy="0.004875" iyz="0.0" izz="0.00075"/>
    </inertial>
  </link>

  <!-- Joint 2: Link 1 to Link 2 (Revolute Y) -->
  <joint name="joint_2" type="revolute">
    <parent link="link_1"/>
    <child link="link_2"/>
    <origin xyz="0 0 0.3" rpy="0 0 0"/>
    <axis xyz="0 1 0"/>
    <limit lower="-1.57" upper="1.57" effort="10.0" velocity="1.0"/>
  </joint>

  <!-- Link 2 -->
  <link name="link_2">
    <visual>
      <origin xyz="0 0 0.2" rpy="0 0 0"/>
      <geometry>
        <cylinder length="0.4" radius="0.04"/>
      </geometry>
      <material name="white"/>
    </visual>
    <collision>
      <origin xyz="0 0 0.2" rpy="0 0 0"/>
      <geometry>
        <cylinder length="0.4" radius="0.04"/>
      </geometry>
    </collision>
    <inertial>
      <origin xyz="0 0 0.2" rpy="0 0 0"/>
      <mass value="0.8"/>
      <inertia ixx="0.011" ixy="0.0" ixz="0.0" iyy="0.011" iyz="0.0" izz="0.00064"/>
    </inertial>
  </link>

  <!-- Joint 3: Link 2 to Link 3 (Revolute Y) -->
  <joint name="joint_3" type="revolute">
    <parent link="link_2"/>
    <child link="link_3"/>
    <origin xyz="0 0 0.4" rpy="0 0 0"/>
    <axis xyz="0 1 0"/>
    <limit lower="-1.57" upper="1.57" effort="10.0" velocity="1.0"/>
  </joint>

  <!-- Link 3 -->
  <link name="link_3">
    <visual>
      <origin xyz="0 0 0.15" rpy="0 0 0"/>
      <geometry>
        <cylinder length="0.3" radius="0.03"/>
      </geometry>
      <material name="red"/>
    </visual>
    <collision>
      <origin xyz="0 0 0.15" rpy="0 0 0"/>
      <geometry>
        <cylinder length="0.3" radius="0.03"/>
      </geometry>
    </collision>
    <inertial>
      <origin xyz="0 0 0.15" rpy="0 0 0"/>
      <mass value="0.6"/>
      <inertia ixx="0.004635" ixy="0.0" ixz="0.0" iyy="0.004635" iyz="0.0" izz="0.00027"/>
    </inertial>
  </link>

  <!-- Joint Fixed: Link 3 to Gripper Base -->
  <joint name="gripper_fixed" type="fixed">
    <parent link="link_3"/>
    <child link="gripper_base"/>
    <origin xyz="0 0 0.3" rpy="0 0 0"/>
  </joint>

  <!-- Gripper Base -->
  <link name="gripper_base">
    <visual>
      <origin xyz="0 0 0.02" rpy="0 0 0"/>
      <geometry>
        <box size="0.06 0.06 0.04"/>
      </geometry>
      <material name="black"/>
    </visual>
    <collision>
      <origin xyz="0 0 0.02" rpy="0 0 0"/>
      <geometry>
        <box size="0.06 0.06 0.04"/>
      </geometry>
    </collision>
    <inertial>
      <origin xyz="0 0 0.02" rpy="0 0 0"/>
      <mass value="0.2"/>
      <inertia ixx="0.000086" ixy="0.0" ixz="0.0" iyy="0.000086" iyz="0.0" izz="0.00012"/>
    </inertial>
  </link>

  <!-- Joint Prismatic: Left Finger -->
  <joint name="left_finger_joint" type="prismatic">
    <parent link="gripper_base"/>
    <child link="left_finger"/>
    <origin xyz="0 0.02 0.04" rpy="0 0 0"/>
    <axis xyz="0 1 0"/>
    <limit lower="0.0" upper="0.04" effort="10.0" velocity="1.0"/>
  </joint>

  <!-- Left Finger -->
  <link name="left_finger">
    <visual>
      <origin xyz="0 0.01 0.04" rpy="0 0 0"/>
      <geometry>
        <box size="0.01 0.02 0.08"/>
      </geometry>
      <material name="gray"/>
    </visual>
    <collision>
      <origin xyz="0 0.01 0.04" rpy="0 0 0"/>
      <geometry>
        <box size="0.01 0.02 0.08"/>
      </geometry>
    </collision>
    <inertial>
      <origin xyz="0 0.01 0.04" rpy="0 0 0"/>
      <mass value="0.05"/>
      <inertia ixx="0.0000283" ixy="0.0" ixz="0.0" iyy="0.000027" iyz="0.0" izz="0.000002"/>
    </inertial>
  </link>

  <!-- Joint Prismatic: Right Finger -->
  <joint name="right_finger_joint" type="prismatic">
    <parent link="gripper_base"/>
    <child link="right_finger"/>
    <origin xyz="0 -0.02 0.04" rpy="0 0 0"/>
    <axis xyz="0 -1 0"/>
    <limit lower="0.0" upper="0.04" effort="10.0" velocity="1.0"/>
  </joint>

  <!-- Right Finger -->
  <link name="right_finger">
    <visual>
      <origin xyz="0 -0.01 0.04" rpy="0 0 0"/>
      <geometry>
        <box size="0.01 0.02 0.08"/>
      </geometry>
      <material name="gray"/>
    </visual>
    <collision>
      <origin xyz="0 -0.01 0.04" rpy="0 0 0"/>
      <geometry>
        <box size="0.01 0.02 0.08"/>
      </geometry>
    </collision>
    <inertial>
      <origin xyz="0 -0.01 0.04" rpy="0 0 0"/>
      <mass value="0.05"/>
      <inertia ixx="0.0000283" ixy="0.0" ixz="0.0" iyy="0.000027" iyz="0.0" izz="0.000002"/>
    </inertial>
  </link>

</robot>
